<robot name="eRobo3" version="1.0">
  <joint name="Joint_1" type="revolute">
    <safety_controller k_position="100.0" k_velocity="40.0" soft_lower_limit="-1.8973" soft_upper_limit="1.8973" />
    <origin rpy="0.00000 0.00000 0.00000" xyz="0.00000 0.00000 0.00000"/>
    <parent link="base_link"/>
    <child link="Link_1"/>
    <axis xyz="0.00000 0.00000 1.00000"/>
    <limit effort="87" lower="-1.9671" upper="1.9671" velocity="2.3925" />
  </joint>
  <joint name="Joint_2" type="revolute">
    <safety_controller k_position="100.0" k_velocity="40.0" soft_lower_limit="-0.7028" soft_upper_limit="0.7028" />
    <origin rpy="0.00000 0.00000 0.00000" xyz="0.00000 0.05300 0.14050"/>
    <parent link="Link_1"/>
    <child link="Link_2"/>
    <axis xyz="0.00000 -1.00000 0.00000"/>
    <limit effort="87" lower="-0.7126" upper="0.7126" velocity="2.3925" />
  </joint>
  <joint name="Joint_3" type="revolute">
    <safety_controller k_position="100.0" k_velocity="40.0" soft_lower_limit="-1.7628" soft_upper_limit="1.7628" />
    <origin rpy="0.00000 0.00000 0.00000" xyz="0.00000 0.00050 0.24350"/>
    <parent link="Link_2"/>
    <child link="Link_3"/>
    <axis xyz="0.00000 -1.00000 0.00000"/>
    <limit effort="87" lower="-1.8326" upper="1.8326" velocity="2.3925" />
  </joint>
  <joint name="Joint_4" type="revolute">
    <safety_controller k_position="100.0" k_velocity="40.0" soft_lower_limit="-1.7628" soft_upper_limit="1.7628" />
    <origin rpy="0.00000 0.00000 0.00000" xyz="0.00000 -0.01400 0.21100"/>
    <parent link="Link_3"/>
    <child link="Link_4"/>
    <axis xyz="0.00000 -1.00000 0.00000"/>
    <limit effort="87" lower="-1.8326" upper="1.8326" velocity="2.3925" />
  </joint>
  <joint name="Joint_5" type="revolute">
    <safety_controller k_position="100.0" k_velocity="40.0" soft_lower_limit="-1.8973" soft_upper_limit="1.8973" />
    <origin rpy="0.00000 0.00000 0.00000" xyz="0.00000 0.04700 0.03900"/>
    <parent link="Link_4"/>
    <child link="Link_5"/>
    <axis xyz="0.00000 0.00000 1.00000"/>
    <limit effort="12" lower="-1.9671" upper="1.9671" velocity="2.8710" />
  </joint>
  <joint name="Joint_6" type="revolute">
    <safety_controller k_position="100.0" k_velocity="40.0" soft_lower_limit="-0.0175" soft_upper_limit="3.7525" />
    <origin rpy="0.00000 0.00000 0.00000" xyz="0.00000 0.06080 0.04700"/>
    <parent link="Link_5"/>
    <child link="Link_6"/>
    <axis xyz="0.00000 -1.00000 0.00000"/>
    <limit effort="12" lower="-0.0873" upper="3.8223" velocity="2.8710" />
  </joint>
  
  
    <joint name="panda_hand_joint" type="fixed">
        <parent link="Link_6" />
        <child link="panda_hand" />
        <origin rpy="-1.5708 1.5708 0" xyz="0 0.01 0.0000" />
    </joint>
    <link name="panda_hand">
        <visual>
            <geometry>
                <mesh filename="package://erob_arm/meshes/hand.dae" />
            </geometry>
        </visual>
        <collision>
            <geometry>
                <mesh filename="package://erob_arm/meshes/hand.stl" />
            </geometry>
        </collision>
    </link>
    <link name="panda_leftfinger">
        <visual>
            <geometry>
                <mesh filename="package://erob_arm/meshes/finger.dae" />
            </geometry>
        </visual>
        <collision>
            <geometry>
                <mesh filename="package://erob_arm/meshes/finger.stl" />
            </geometry>
        </collision>
    </link>
    <link name="panda_rightfinger">
        <visual>
            <origin rpy="0 0 3.14159265359" xyz="0 0 0" />
            <geometry>
                <mesh filename="package://erob_arm/meshes/finger.dae" />
            </geometry>
        </visual>
        <collision>
            <origin rpy="0 0 3.14159265359" xyz="0 0 0" />
            <geometry>
                <mesh filename="package://erob_arm/meshes/finger.stl" />
            </geometry>
        </collision>
    </link>
    <joint name="panda_finger_joint1" type="prismatic">
        <parent link="panda_hand" />
        <child link="panda_leftfinger" />
        <origin rpy="0 0 0" xyz="0 0 0.0584" />
        <axis xyz="0 1 0" />
        <limit effort="20" lower="0.0" upper="0.04" velocity="0.2" />
    </joint>
    <joint name="panda_finger_joint2" type="prismatic">
        <parent link="panda_hand" />
        <child link="panda_rightfinger" />
        <origin rpy="0 0 0" xyz="0 0 0.0584" />
        <axis xyz="0 -1 0" />
        <limit effort="20" lower="0.0" upper="0.04" velocity="0.2" />
        <mimic joint="panda_finger_joint1" />
    </joint>
    
  
  <link name="Link_1">
    <collision name="Link_1_collision">
      <origin rpy="0.00000 0.00000 0.00000" xyz="0.00000 0.00000 0.00000"/>
      <geometry>
        <mesh filename="package://erob_arm/meshes/Link_1.stl" scale="1.00000 1.00000 1.00000"/>
      </geometry>
    </collision>
    <inertial>
      <inertia ixx="0.00054" ixy="0.00000" ixz="0.00000" iyy="0.00052" iyz="0.00000" izz="0.00054"/>
      <origin rpy="0.00000 0.00000 0.00000" xyz="0.00000 0.00308 0.13617"/>
      <mass value="0.50622"/>
    </inertial>
    <visual name="Link_1_visual">
      <origin rpy="0.00000 0.00000 0.00000" xyz="0.00000 0.00000 0.00000"/>
      <material name="#ffffffff"/>
      <geometry>
        <mesh filename="package://erob_arm/meshes/Link_1.stl" scale="1.00000 1.00000 1.00000"/>
      </geometry>
    </visual>
  </link>
  <link name="Link_2">
    <collision name="Link_2_collision">
      <origin rpy="0.00000 0.00000 0.00000" xyz="0.00000 0.00000 0.00000"/>
      <geometry>
        <mesh filename="package://erob_arm/meshes/Link_2.stl" scale="1.00000 1.00000 1.00000"/>
      </geometry>
    </collision>
    <inertial>
      <inertia ixx="0.00157" ixy="0.00000" ixz="0.00000" iyy="0.00156" iyz="0.00000" izz="0.00119"/>
      <origin rpy="0.00000 0.00000 0.00000" xyz="0.00000 0.04217 0.11937"/>
      <mass value="1.16203"/>
    </inertial>
    <visual name="Link_2_visual">
      <origin rpy="0.00000 0.00000 0.00000" xyz="0.00000 0.00000 0.00000"/>
      <material name="#ffffffff"/>
      <geometry>
        <mesh filename="package://erob_arm/meshes/Link_2.stl" scale="1.00000 1.00000 1.00000"/>
      </geometry>
    </visual>
  </link>
  <link name="Link_3">
    <collision name="Link_3_collision">
      <origin rpy="0.00000 0.00000 0.00000" xyz="0.00000 0.00000 0.00000"/>
      <geometry>
        <mesh filename="package://erob_arm/meshes/Link_3.stl" scale="1.00000 1.00000 1.00000"/>
      </geometry>
    </collision>
    <inertial>
      <inertia ixx="0.00081" ixy="0.00000" ixz="0.00000" iyy="0.00091" iyz="-0.00001" izz="0.00062"/>
      <origin rpy="0.00000 0.00000 0.00000" xyz="0.00000 -0.05451 0.09532"/>
      <mass value="0.77552"/>
    </inertial>
    <visual name="Link_3_visual">
      <origin rpy="0.00000 0.00000 0.00000" xyz="0.00000 0.00000 0.00000"/>
      <material name="#ffffffff"/>
      <geometry>
        <mesh filename="package://erob_arm/meshes/Link_3.stl" scale="1.00000 1.00000 1.00000"/>
      </geometry>
    </visual>
  </link>
  <link name="Link_4">
    <collision name="Link_4_collision">
      <origin rpy="0.00000 0.00000 0.00000" xyz="0.00000 0.00000 0.00000"/>
      <geometry>
        <mesh filename="package://erob_arm/meshes/Link_4.stl" scale="1.00000 1.00000 1.00000"/>
      </geometry>
    </collision>
    <inertial>
      <inertia ixx="0.00025" ixy="0.00000" ixz="0.00000" iyy="0.00024" iyz="0.00000" izz="0.00026"/>
      <origin rpy="0.00000 0.00000 0.00000" xyz="0.00001 0.04110 0.00150"/>
      <mass value="0.31668"/>
    </inertial>
    <visual name="Link_4_visual">
      <origin rpy="0.00000 0.00000 0.00000" xyz="0.00000 0.00000 0.00000"/>
      <material name="#ffffffff"/>
      <geometry>
        <mesh filename="package://erob_arm/meshes/Link_4.stl" scale="1.00000 1.00000 1.00000"/>
      </geometry>
    </visual>
  </link>
  <link name="Link_5">
    <collision name="Link_5_collision">
      <origin rpy="0.00000 0.00000 0.00000" xyz="0.00000 0.00000 0.00000"/>
      <geometry>
        <mesh filename="package://erob_arm/meshes/Link_5.stl" scale="1.00000 1.00000 1.00000"/>
      </geometry>
    </collision>
    <inertial>
      <inertia ixx="0.00025" ixy="0.00000" ixz="0.00000" iyy="0.00026" iyz="0.00000" izz="0.00024"/>
      <origin rpy="0.00000 0.00000 0.00000" xyz="-0.00001 0.00150 0.04110"/>
      <mass value="0.31668"/>
    </inertial>
    <visual name="Link_5_visual">
      <origin rpy="0.00000 0.00000 0.00000" xyz="0.00000 0.00000 0.00000"/>
      <material name="#ffffffff"/>
      <geometry>
        <mesh filename="package://erob_arm/meshes/Link_5.stl" scale="1.00000 1.00000 1.00000"/>
      </geometry>
    </visual>
  </link>
  <link name="Link_6">
    <collision name="Link_6_collision">
      <origin rpy="0.00000 0.00000 0.00000" xyz="0.00000 0.00000 0.00000"/>
      <geometry>
        <mesh filename="package://erob_arm/meshes/Link_6.stl" scale="1.00000 1.00000 1.00000"/>
      </geometry>
    </collision>
    <inertial>
      <inertia ixx="0.00004" ixy="0.00000" ixz="0.00000" iyy="0.00007" iyz="0.00000" izz="0.00004"/>
      <origin rpy="0.00000 0.00000 0.00000" xyz="0.00000 -0.00578 0.00013"/>
      <mass value="0.10121"/>
    </inertial>
    <visual name="Link_6_visual">
      <origin rpy="0.00000 0.00000 0.00000" xyz="0.00000 0.00000 0.00000"/>
      <material name="#ffffffff"/>
      <geometry>
        <mesh filename="package://erob_arm/meshes/Link_6.stl" scale="1.00000 1.00000 1.00000"/>
      </geometry>
    </visual>
  </link>
  <link name="base_link">
    <collision name="base_link_collision">
      <origin rpy="0.00000 0.00000 0.00000" xyz="0.00000 0.00000 0.00000"/>
      <geometry>
        <mesh filename="package://erob_arm/meshes/base_link.stl" scale="1.00000 1.00000 1.00000"/>
      </geometry>
    </collision>
    <inertial>
      <inertia ixx="0.00083" ixy="0.00001" ixz="0.00001" iyy="0.00085" iyz="0.00003" izz="0.00110"/>
      <origin rpy="0.00000 0.00000 0.00000" xyz="0.00095 -0.00172 0.03600"/>
      <mass value="0.47602"/>
    </inertial>
    <visual name="base_link_visual">
      <origin rpy="0.00000 0.00000 0.00000" xyz="0.00000 0.00000 0.00000"/>
      <material name="base"/>
      <geometry>
        <mesh filename="package://erob_arm/meshes/base_link.stl" scale="1.00000 1.00000 1.00000"/>
      </geometry>
    </visual>
  </link>
  

  <material name="#ffffffff">
    <color rgba="0.50000 0.50000 0.50000 1.0000"/>
  </material>
    <material name="base">
    <color rgba="0.40000 0.40000 0.40000 1.0000"/>
  </material>
</robot>
